[2023-02-27 20:34:57,422]^;WARNING^;88^;_internal.py^;_log()^; * Debugger is active!
[2023-02-27 20:34:57,432]^;INFO^;88^;_internal.py^;_log()^; * Debugger PIN: 998-459-131
[2023-02-27 20:34:57,532]^;INFO^;88^;_internal.py^;_log()^; * Running on http://127.0.0.1:5000/ (Press CTRL+C to quit)
[2023-02-27 20:35:28,415]^;INFO^;8^;app.py^;index()^;we are testing logging module
[2023-02-27 20:35:28,415]^;INFO^;88^;_internal.py^;_log()^;127.0.0.1 - - [27/Feb/2023 20:35:28] "GET / HTTP/1.1" 200 -
[2023-02-27 20:39:54,436]^;INFO^;88^;_internal.py^;_log()^; * Detected change in 'G:\\DataScience_Projects\\Fourth_Project\\Insurance_Premium\\insurancepre\\exception\\__init__.py', reloading
[2023-02-27 20:39:54,792]^;INFO^;88^;_internal.py^;_log()^; * Detected change in 'G:\\DataScience_Projects\\Fourth_Project\\Insurance_Premium\\insurancepre\\exception\\__init__.py', reloading
